Workbook

Sheet Summary
A1: Nashr — Financial Summary (SAR)
A2: 36-month model. Change inputs on the Assumptions sheet; all sheets recalculate.
B4: Year 1 | C4: Year 2 | D4: Year 3
A5: Revenue | B5: ='P&L'!AL7 | C5: ='P&L'!AM7 | D5: ='P&L'!AN7
A6: Gross profit | B6: ='P&L'!AL15 | C6: ='P&L'!AM15 | D6: ='P&L'!AN15
A7: Gross margin | B7: ='P&L'!AL16 | C7: ='P&L'!AM16 | D7: ='P&L'!AN16
A8: Total opex | B8: ='P&L'!AL24 | C8: ='P&L'!AM24 | D8: ='P&L'!AN24
A9: EBITDA | B9: ='P&L'!AL25 | C9: ='P&L'!AM25 | D9: ='P&L'!AN25
A10: EBITDA margin | B10: ='P&L'!AL26 | C10: ='P&L'!AM26 | D10: ='P&L'!AN26
A11: Ending MRR | B11: ='P&L'!AL28 | C11: ='P&L'!AM28 | D11: ='P&L'!AN28
A12: Ending ARR run-rate | B12: ='P&L'!AL29 | C12: ='P&L'!AM29 | D12: ='P&L'!AN29
A13: Ending paying brands | B13: =Customers!M6 | C13: =Customers!Y6 | D13: =Customers!AK6
A14: Ending headcount | B14: =Headcount!N9 | C14: =Headcount!Z9 | D14: =Headcount!AL9
A15: Ending cash | B15: =Cash!M5 | C15: =Cash!Y5 | D15: =Cash!AK5
A17: Blended LTV:CAC | B17: ='Unit Economics'!B25
A18: Blended CAC payback (months) | B18: ='Unit Economics'!B26
A19: Minimum cash balance (36m) | B19: =Cash!B8
A20: Seed raise | B20: =Assumptions!$B$57

Sheet Assumptions
A1: Nashr — Model Assumptions (SAR)
A2: Yellow cells are inputs. Everything else is formula-driven.
A5: Pricing (monthly, SAR, ex-VAT)
A6: Starter price | B6: 149
A7: Pro price | B7: 399
A8: Agency price | B8: 799
A9: Enterprise avg contract / month | B9: 4500 | C9: Custom deals; blended average
A10: Annual plan discount (2 months free) | B10: 0.16666667
A11: Share of customers on annual | B11: 0.3
A12: Top-up revenue as % of subscription | B12: 0.12 | C12: Credit top-ups + extra seats/brands
A14: Plan mix of paying customers
A15: Starter | B15: 0.45
A16: Pro | B16: 0.4
A17: Agency | B17: 0.13
A18: Enterprise | B18: 0.02
A20: Acquisition
A21: Trials in month 1 | B21: 180 | C21: Waitlist + design partners
A22: Monthly trial growth, year 1 | B22: 0.24
A23: Monthly trial growth, year 2 | B23: 0.09
A24: Monthly trial growth, year 3 | B24: 0.03
A25: Trial → paid conversion | B25: 0.12
A26: Monthly logo churn | B26: 0.04 | C26: Target <4%; SMB SaaS median 3–6%
A27: Blended CAC per paying customer | B27: 650 | C27: Salla/Zid app store, content, paid, agency rev-share
A29: Cost of revenue (per paying brand per month)
A30: AI/model + media cost — Starter | B30: 22 | C30: 200 credits × ~0.11 SAR
A31: AI/model + media cost — Pro | B31: 70 | C31: 700 credits × ~0.10 SAR
A32: AI/model + media cost — Agency | B32: 190 | C32: 2,000 credits × ~0.095 SAR
A33: AI/model + media cost — Enterprise | B33: 900
A34: Hosting/infra per brand (KSA region) | B34: 6
A35: WhatsApp/SMS pass-through per brand | B35: 9 | C35: Cloud API conversation fees, avg
A36: Payment processing % of revenue | B36: 0.028 | C36: Tap/Moyasar mada+cards blend
A37: Support/QA cost per brand | B37: 8 | C37: Arabic QA reviewers, tier-1 support
A39: Operating expenses
A40: Software & tools / month | B40: 9000
A41: Office & admin / month | B41: 12000
A42: Legal, accounting, compliance / month | B42: 7000
A43: Marketing base (content, events) / month | B43: 15000 | C43: Excludes CAC-driven spend (new paying × CAC)
A44: VAT (pass-through on collections; not in P&L) | B44: 0.15
A46: Headcount (SAR fully loaded per month)
A47: Founder / CEO | B47: 25000
...

Sheet Headcount
A1: Role | B1: Cost/mo | C1: Oct-26 | D1: Nov-26 | E1: Dec-26 | F1: Jan-27 | G1: Feb-27 | H1: Mar-27 | I1: Apr-27 | J1: May-27 | K1: Jun-27 | L1: Jul-27 | M1: Aug-27 | N1: Sep-27 | O1: Oct-27 | P1: Nov-27 | Q1: Dec-27 | R1: Jan-28 | S1: Feb-28 | T1: Mar-28 | U1: Apr-28 | V1: May-28 | W1: Jun-28 | X1: Jul-28 | Y1: Aug-28 | Z1: Sep-28 | AA1: Oct-28 | AB1: Nov-28 | AC1: Dec-28 | AD1: Jan-29 | AE1: Feb-29 | AF1: Mar-29 | AG1: Apr-29 | AH1: May-29 | AI1: Jun-29 | AJ1: Jul-29 | AK1: Aug-29 | AL1: Sep-29
A2: Founder / CEO | B2: =Assumptions!$B$47 | C2: 1 | D2: 1 | E2: 1 | F2: 1 | G2: 1 | H2: 1 | I2: 1 | J2: 1 | K2: 1 | L2: 1 | M2: 1 | N2: 1 | O2: 1 | P2: 1 | Q2: 1 | R2: 1 | S2: 1 | T2: 1 | U2: 1 | V2: 1 | W2: 1 | X2: 1 | Y2: 1 | Z2: 1 | AA2: 1 | AB2: 1 | AC2: 1 | AD2: 1 | AE2: 1 | AF2: 1 | AG2: 1 | AH2: 1 | AI2: 1 | AJ2: 1 | AK2: 1 | AL2: 1
A3: Engineer | B3: =Assumptions!$B$48 | C3: 1 | D3: 1 | E3: 1 | F3: 2 | G3: 2 | H3: 2 | I3: 2 | J3: 2 | K3: 3 | L3: 3 | M3: 3 | N3: 3 | O3: 3 | P3: 3 | Q3: 4 | R3: 4 | S3: 4 | T3: 4 | U3: 4 | V3: 4 | W3: 4 | X3: 4 | Y3: 4 | Z3: 4 | AA3: 6 | AB3: 6 | AC3: 6 | AD3: 6 | AE3: 6 | AF3: 6 | AG3: 8 | AH3: 8 | AI3: 8 | AJ3: 8 | AK3: 8 | AL3: 8
A4: AI / prompt engineer | B4: =Assumptions!$B$49 | C4: 1 | D4: 1 | E4: 1 | F4: 1 | G4: 1 | H4: 1 | I4: 2 | J4: 2 | K4: 2 | L4: 2 | M4: 2 | N4: 2 | O4: 2 | P4: 2 | Q4: 2 | R4: 2 | S4: 2 | T4: 2 | U4: 2 | V4: 2 | W4: 2 | X4: 2 | Y4: 2 | Z4: 2 | AA4: 2 | AB4: 2 | AC4: 2 | AD4: 2 | AE4: 2 | AF4: 2 | AG4: 2 | AH4: 2 | AI4: 2 | AJ4: 2 | AK4: 2 | AL4: 2
A5: Designer | B5: =Assumptions!$B$50 | C5: 0 | D5: 0 | E5: 0 | F5: 0 | G5: 1 | H5: 1 | I5: 1 | J5: 1 | K5: 1 | L5: 1 | M5: 1 | N5: 1 | O5: 1 | P5: 1 | Q5: 1 | R5: 1 | S5: 1 | T5: 1 | U5: 1 | V5: 1 | W5: 1 | X5: 1 | Y5: 1 | Z5: 1 | AA5: 1 | AB5: 1 | AC5: 1 | AD5: 1 | AE5: 1 | AF5: 1 | AG5: 1 | AH5: 1 | AI5: 1 | AJ5: 1 | AK5: 1 | AL5: 1
A6: Growth / partnerships | B6: =Assumptions!$B$51 | C6: 0 | D6: 0 | E6: 0 | F6: 1 | G6: 1 | H6: 1 | I6: 1 | J6: 1 | K6: 1 | L6: 1 | M6: 1 | N6: 1 | O6: 1 | P6: 1 | Q6: 1 | R6: 2 | S6: 2 | T6: 2 | U6: 2 | V6: 2 | W6: 2 | X6: 2 | Y6: 2 | Z6: 2 | AA6: 2 | AB6: 2 | AC6: 2 | AD6: 3 | AE6: 3 | AF6: 3 | AG6: 3 | AH6: 3 | AI6: 3 | AJ6: 3 | AK6: 3 | AL6: 3
A7: Customer success / Arabic QA | B7: =Assumptions!$B$52 | C7: 1 | D7: 1 | E7: 1 | F7: 1 | G7: 2 | H7: 2 | I7: 2 | J7: 2 | K7: 2 | L7: 2 | M7: 3 | N7: 3 | O7: 3 | P7: 3 | Q7: 3 | R7: 3 | S7: 3 | T7: 3 | U7: 5 | V7: 5 | W7: 5 | X7: 5 | Y7: 5 | Z7: 5 | AA7: 8 | AB7: 8 | AC7: 8 | AD7: 8 | AE7: 8 | AF7: 8 | AG7: 12 | AH7: 12 | AI7: 12 | AJ7: 12 | AK7: 12 | AL7: 12
A8: Enterprise sales | B8: =Assumptions!$B$53 | C8: 0 | D8: 0 | E8: 0 | F8: 0 | G8: 0 | H8: 0 | I8: 0 | J8: 0 | K8: 0 | L8: 1 | M8: 1 | N8: 1 | O8: 1 | P8: 1 | Q8: 1 | R8: 1 | S8: 1 | T8: 1 | U8: 1 | V8: 1 | W8: 1 | X8: 2 | Y8: 2 | Z8: 2 | AA8: 2 | AB8: 2 | AC8: 2 | AD8: 2 | AE8: 2 | AF8: 2 | AG8: 3 | AH8: 3 | AI8: 3 | AJ8: 3 | AK8: 3 | AL8: 3
A9: Total headcount | C9: =SUM(C2:C8) | D9: =SUM(D2:D8) | E9: =SUM(E2:E8) | F9: =SUM(F2:F8) | G9: =SUM(G2:G8) | H9: =SUM(H2:H8) | I9: =SUM(I2:I8) | J9: =SUM(J2:J8) | ... AL9: =SUM(AL2:AL8)
A10: Total payroll (SAR) | C10: =C2*$B$2+C3*$B$3+C4*$B$4+C5*$B$5+C6*$B$6+C7*$B$7+C8*$B$8 | D10: =D2*$B$2+D3*$B$3+D4*$B$4+D5*$B$5+D6*$B$6+D7*$B$7+D8*$B$8 | E10: =E2*$B$2+E3*$B$3+E4*$B$4+E5*$B$5+E6*$B$6+E7*$B$7+E8*$B$8 | F10: =F2*$B$2+F3*$B$3+F4*$B$4+F5*$B$5+F6*$B$6+F7*$B$7+F8*$B$8 | G10: =G2*$B$2+G3*$B$3+G4*$B$4+G5*$B$5+G6*$B$6+G7*$B$7+G8*$B$8 | H10: =H2*$B$2+H3*$B$3+H4*$B$4+H5*$B$5+H6*$B$6+H7*$B$7+H8*$B$8 | I10: =I2*$B$2+I3*$B$3+I4*$B$4+I5*$B$5+I6*$B$6+I7*$B$7+I8*$B$8 | J10: =J2*$B$2+J3*$B$3+J4*$B$4+J5*$B$5+J6*$B$6+J7*$B$7+J8*$B$8 | ... AL10: =AL2*$B$2+AL3*$B$3+AL4*$B$4+AL5*$B$5+AL6*$B$6+AL7*$B$7+AL8*$B$8

Sheet Customers
A1: Metric | B1: Oct-26 | C1: Nov-26 | D1: Dec-26 | E1: Jan-27 | F1: Feb-27 | G1: Mar-27 | H1: Apr-27 | I1: May-27 | J1: Jun-27 | K1: Jul-27 | L1: Aug-27 | M1: Sep-27 | N1: Oct-27 | O1: Nov-27 | P1: Dec-27 | Q1: Jan-28 | R1: Feb-28 | S1: Mar-28 | T1: Apr-28 | U1: May-28 | V1: Jun-28 | W1: Jul-28 | X1: Aug-28 | Y1: Sep-28 | Z1: Oct-28 | AA1: Nov-28 | AB1: Dec-28 | AC1: Jan-29 | AD1: Feb-29 | AE1: Mar-29 | AF1: Apr-29 | AG1: May-29 | AH1: Jun-29 | AI1: Jul-29 | AJ1: Aug-29 | AK1: Sep-29
A2: Month # | B2: 1 | C2: 2 | D2: 3 | E2: 4 | F2: 5 | G2: 6 | H2: 7 | I2: 8 | J2: 9 | K2: 10 | L2: 11 | M2: 12 | N2: 13 | O2: 14 | P2: 15 | Q2: 16 | R2: 17 | S2: 18 | T2: 19 | U2: 20 | V2: 21 | W2: 22 | X2: 23 | Y2: 24 | Z2: 25 | AA2: 26 | AB2: 27 | AC2: 28 | AD2: 29 | AE2: 30 | AF2: 31 | AG2: 32 | AH2: 33 | AI2: 34 | AJ2: 35 | AK2: 36
A3: Trials | B3: =Assumptions!$B$21 | C3: =ROUND(B3*(1+IF(C2<=12,Assumptions!$B$22,IF(C2<=24,Assumptions!$B$23,Assumptions!$B$24))),0) | D3: =ROUND(C3*(1+IF(D2<=12,Assumptions!$B$22,IF(D2<=24,Assumptions!$B$23,Assumptions!$B$24))),0) | E3: =ROUND(D3*(1+IF(E2<=12,Assumptions!$B$22,IF(E2<=24,Assumptions!$B$23,Assumptions!$B$24))),0) | F3: =ROUND(E3*(1+IF(F2<=12,Assumptions!$B$22,IF(F2<=24,Assumptions!$B$23,Assumptions!$B$24))),0) | G3: =ROUND(F3*(1+IF(G2<=12,Assumptions!$B$22,IF(G2<=24,Assumptions!$B$23,Assumptions!$B$24))),0) | H3: =ROUND(G3*(1+IF(H2<=12,Assumptions!$B$22,IF(H2<=24,Assumptions!$B$23,Assumptions!$B$24))),0) | I3: =ROUND(H3*(1+IF(I2<=12,Assumptions!$B$22,IF(I2<=24,Assumptions!$B$23,Assumptions!$B$24))),0) | J3: =ROUND(I3*(1+IF(J2<=12,Assumptions!$B$22,IF(J2<=24,Assumptions!$B$23,Assumptions!$B$24))),0) | ... AK3: =ROUND(AJ3*(1+IF(AK2<=12,Assumptions!$B$22,IF(AK2<=24,Assumptions!$B$23,Assumptions!$B$24))),0)
A4: New paying | B4: =ROUND(B3*Assumptions!$B$25,0) | C4: =ROUND(C3*Assumptions!$B$25,0) | D4: =ROUND(D3*Assumptions!$B$25,0) | E4: =ROUND(E3*Assumptions!$B$25,0) | F4: =ROUND(F3*Assumptions!$B$25,0) | G4: =ROUND(G3*Assumptions!$B$25,0) | H4: =ROUND(H3*Assumptions!$B$25,0) | I4: =ROUND(I3*Assumptions!$B$25,0) | ... AK4: =ROUND(AK3*Assumptions!$B$25,0)
A5: Churned | B5: 0 | C5: =ROUND(B6*Assumptions!$B$26,0) | D5: =ROUND(C6*Assumptions!$B$26,0) | E5: =ROUND(D6*Assumptions!$B$26,0) | F5: =ROUND(E6*Assumptions!$B$26,0) | G5: =ROUND(F6*Assumptions!$B$26,0) | H5: =ROUND(G6*Assumptions!$B$26,0) | I5: =ROUND(H6*Assumptions!$B$26,0) | J5: =ROUND(I6*Assumptions!$B$26,0) | ... AK5: =ROUND(AJ6*Assumptions!$B$26,0)
A6: Ending paying brands | B6: =B4 | C6: =B6+C4-C5 | D6: =C6+D4-D5 | E6: =D6+E4-E5 | F6: =E6+F4-F5 | G6: =F6+G4-G5 | H6: =G6+H4-H5 | I6: =H6+I4-I5 | J6: =I6+J4-J5 | ... AK6: =AJ6+AK4-AK5
A7: — Starter | B7: =ROUND(B6*Assumptions!$B$15,0) | C7: =ROUND(C6*Assumptions!$B$15,0) | D7: =ROUND(D6*Assumptions!$B$15,0) | E7: =ROUND(E6*Assumptions!$B$15,0) | F7: =ROUND(F6*Assumptions!$B$15,0) | G7: =ROUND(G6*Assumptions!$B$15,0) | H7: =ROUND(H6*Assumptions!$B$15,0) | I7: =ROUND(I6*Assumptions!$B$15,0) | ... AK7: =ROUND(AK6*Assumptions!$B$15,0)
A8: — Pro | B8: =ROUND(B6*Assumptions!$B$16,0) | C8: =ROUND(C6*Assumptions!$B$16,0) | D8: =ROUND(D6*Assumptions!$B$16,0) | E8: =ROUND(E6*Assumptions!$B$16,0) | F8: =ROUND(F6*Assumptions!$B$16,0) | G8: =ROUND(G6*Assumptions!$B$16,0) | H8: =ROUND(H6*Assumptions!$B$16,0) | I8: =ROUND(I6*Assumptions!$B$16,0) | ... AK8: =ROUND(AK6*Assumptions!$B$16,0)
A9: — Agency | B9: =ROUND(B6*Assumptions!$B$17,0) | C9: =ROUND(C6*Assumptions!$B$17,0) | D9: =ROUND(D6*Assumptions!$B$17,0) | E9: =ROUND(E6*Assumptions!$B$17,0) | F9: =ROUND(F6*Assumptions!$B$17,0) | G9: =ROUND(G6*Assumptions!$B$17,0) | H9: =ROUND(H6*Assumptions!$B$17,0) | I9: =ROUND(I6*Assumptions!$B$17,0) | ... AK9: =ROUND(AK6*Assumptions!$B$17,0)
A10: — Enterprise | B10: =B6-B7-B8-B9 | C10: =C6-C7-C8-C9 | D10: =D6-D7-D8-D9 | E10: =E6-E7-E8-E9 | F10: =F6-F7-F8-F9 | G10: =G6-G7-G8-G9 | H10: =H6-H7-H8-H9 | I10: =I6-I7-I8-I9 | ... AK10: =AK6-AK7-AK8-AK9

Sheet P&L
A1: SAR | B1: Oct-26 | C1: Nov-26 | D1: Dec-26 | E1: Jan-27 | F1: Feb-27 | G1: Mar-27 | H1: Apr-27 | I1: May-27 | J1: Jun-27 | K1: Jul-27 | L1: Aug-27 | M1: Sep-27 | N1: Oct-27 | O1: Nov-27 | P1: Dec-27 | Q1: Jan-28 | R1: Feb-28 | S1: Mar-28 | T1: Apr-28 | U1: May-28 | V1: Jun-28 | W1: Jul-28 | X1: Aug-28 | Y1: Sep-28 | Z1: Oct-28 | AA1: Nov-28 | AB1: Dec-28 | AC1: Jan-29 | AD1: Feb-29 | AE1: Mar-29 | AF1: Apr-29 | AG1: May-29 | AH1: Jun-29 | AI1: Jul-29 | AJ1: Aug-29 | AK1: Sep-29 | AL1: Year 1 | AM1: Year 2 | AN1: Year 3
A2: Subscription revenue — Starter | B2: =Customers!B7*Assumptions!$B$6*(1-Assumptions!$B$11*Assumptions!$B$10) | C2: =Customers!C7*Assumptions!$B$6*(1-Assumptions!$B$11*Assumptions!$B$10) | D2: =Customers!D7*Assumptions!$B$6*(1-Assumptions!$B$11*Assumptions!$B$10) | E2: =Customers!E7*Assumptions!$B$6*(1-Assumptions!$B$11*Assumptions!$B$10) | F2: =Customers!F7*Assumptions!$B$6*(1-Assumptions!$B$11*Assumptions!$B$10) | G2: =Customers!G7*Assumptions!$B$6*(1-Assumptions!$B$11*Assumptions!$B$10) | H2: =Customers!H7*Assumptions!$B$6*(1-Assumptions!$B$11*Assumptions!$B$10) | I2: =Customers!I7*Assumptions!$B$6*(1-Assumptions!$B$11*Assumptions!$B$10) | ... AK2: =Customers!AK7*Assumptions!$B$6*(1-Assumptions!$B$11*Assumptions!$B$10) | AL2: =SUM(B2:M2) | AM2: =SUM(N2:Y2) | AN2: =SUM(Z2:AK2)
A3: Subscription revenue — Pro | B3: =Customers!B8*Assumptions!$B$7*(1-Assumptions!$B$11*Assumptions!$B$10) | C3: =Customers!C8*Assumptions!$B$7*(1-Assumptions!$B$11*Assumptions!$B$10) | D3: =Customers!D8*Assumptions!$B$7*(1-Assumptions!$B$11*Assumptions!$B$10) | E3: =Customers!E8*Assumptions!$B$7*(1-Assumptions!$B$11*Assumptions!$B$10) | F3: =Customers!F8*Assumptions!$B$7*(1-Assumptions!$B$11*Assumptions!$B$10) | G3: =Customers!G8*Assumptions!$B$7*(1-Assumptions!$B$11*Assumptions!$B$10) | H3: =Customers!H8*Assumptions!$B$7*(1-Assumptions!$B$11*Assumptions!$B$10) | I3: =Customers!I8*Assumptions!$B$7*(1-Assumptions!$B$11*Assumptions!$B$10) | ... AK3: =Customers!AK8*Assumptions!$B$7*(1-Assumptions!$B$11*Assumptions!$B$10) | AL3: =SUM(B3:M3) | AM3: =SUM(N3:Y3) | AN3: =SUM(Z3:AK3)
A4: Subscription revenue — Agency | B4: =Customers!B9*Assumptions!$B$8*(1-Assumptions!$B$11*Assumptions!$B$10) | C4: =Customers!C9*Assumptions!$B$8*(1-Assumptions!$B$11*Assumptions!$B$10) | D4: =Customers!D9*Assumptions!$B$8*(1-Assumptions!$B$11*Assumptions!$B$10) | E4: =Customers!E9*Assumptions!$B$8*(1-Assumptions!$B$11*Assumptions!$B$10) | F4: =Customers!F9*Assumptions!$B$8*(1-Assumptions!$B$11*Assumptions!$B$10) | G4: =Customers!G9*Assumptions!$B$8*(1-Assumptions!$B$11*Assumptions!$B$10) | H4: =Customers!H9*Assumptions!$B$8*(1-Assumptions!$B$11*Assumptions!$B$10) | I4: =Customers!I9*Assumptions!$B$8*(1-Assumptions!$B$11*Assumptions!$B$10) | ... AK4: =Customers!AK9*Assumptions!$B$8*(1-Assumptions!$B$11*Assumptions!$B$10) | AL4: =SUM(B4:M4) | AM4: =SUM(N4:Y4) | AN4: =SUM(Z4:AK4)
A5: Subscription revenue — Enterprise | B5: =Customers!B10*Assumptions!$B$9 | C5: =Customers!C10*Assumptions!$B$9 | D5: =Customers!D10*Assumptions!$B$9 | E5: =Customers!E10*Assumptions!$B$9 | F5: =Customers!F10*Assumptions!$B$9 | G5: =Customers!G10*Assumptions!$B$9 | H5: =Customers!H10*Assumptions!$B$9 | I5: =Customers!I10*Assumptions!$B$9 | ... AK5: =Customers!AK10*Assumptions!$B$9 | AL5: =SUM(B5:M5) | AM5: =SUM(N5:Y5) | AN5: =SUM(Z5:AK5)
A6: Top-ups, seats, brands | B6: =SUM(B2:B5)*Assumptions!$B$12 | C6: =SUM(C2:C5)*Assumptions!$B$12 | D6: =SUM(D2:D5)*Assumptions!$B$12 | E6: =SUM(E2:E5)*Assumptions!$B$12 | F6: =SUM(F2:F5)*Assumptions!$B$12 | G6: =SUM(G2:G5)*Assumptions!$B$12 | H6: =SUM(H2:H5)*Assumptions!$B$12 | I6: =SUM(I2:I5)*Assumptions!$B$12 | ... AK6: =SUM(AK2:AK5)*Assumptions!$B$12 | AL6: =SUM(B6:M6) | AM6: =SUM(N6:Y6) | AN6: =SUM(Z6:AK6)
A7: TOTAL REVENUE | B7: =SUM(B2:B6) | C7: =SUM(C2:C6) | D7: =SUM(D2:D6) | E7: =SUM(E2:E6) | F7: =SUM(F2:F6) | G7: =SUM(G2:G6) | H7: =SUM(H2:H6) | I7: =SUM(I2:I6) | ... AK7: =SUM(AK2:AK6) | AL7: =SUM(B7:M7) | AM7: =SUM(N7:Y7) | AN7: =SUM(Z7:AK7)
A9: AI model + media | B9: =Customers!B7*Assumptions!$B$30+Customers!B8*Assumptions!$B$31+Customers!B9*Assumptions!$B$32+Customers!B10*Assumptions!$B$33 | C9: =Customers!C7*Assumptions!$B$30+Customers!C8*Assumptions!$B$31+Customers!C9*Assumptions!$B$32+Customers!C10*Assumptions!$B$33 | D9: =Customers!D7*Assumptions!$B$30+Customers!D8*Assumptions!$B$31+Customers!D9*Assumptions!$B$32+Customers!D10*Assumptions!$B$33 | E9: =Customers!E7*Assumptions!$B$30+Customers!E8*Assumptions!$B$31+Customers!E9*Assumptions!$B$32+Customers!E10*Assumptions!$B$33 | F9: =Customers!F7*Assumptions!$B$30+Customers!F8*Assumptions!$B$31+Customers!F9*Assumptions!$B$32+Customers!F10*Assumptions!$B$33 | G9: =Customers!G7*Assumptions!$B$30+Customers!G8*Assumptions!$B$31+Customers!G9*Assumptions!$B$32+Customers!G10*Assumptions!$B$33 | H9: =Customers!H7*Assumptions!$B$30+Customers!H8*Assumptions!$B$31+Customers!H9*Assumptions!$B$32+Customers!H10*Assumptions!$B$33 | I9: =Customers!I7*Assumptions!$B$30+Customers!I8*Assumptions!$B$31+Customers!I9*Assumptions!$B$32+Customers!I10*Assumptions!$B$33 | ... AK9: =Customers!AK7*Assumptions!$B$30+Customers!AK8*Assumptions!$B$31+Customers!AK9*Assumptions!$B$32+Customers!AK10*Assumptions!$B$33 | AL9: =SUM(B9:M9) | AM9: =SUM(N9:Y9) | AN9: =SUM(Z9:AK9)
A10: Infra (KSA region) | B10: =Customers!B6*Assumptions!$B$34 | C10: =Customers!C6*Assumptions!$B$34 | D10: =Customers!D6*Assumptions!$B$34 | E10: =Customers!E6*Assumptions!$B$34 | F10: =Customers!F6*Assumptions!$B$34 | G10: =Customers!G6*Assumptions!$B$34 | H10: =Customers!H6*Assumptions!$B$34 | I10: =Customers!I6*Assumptions!$B$34 | ... AK10: =Customers!AK6*Assumptions!$B$34 | AL10: =SUM(B10:M10) | AM10: =SUM(N10:Y10) | AN10: =SUM(Z10:AK10)
A11: WhatsApp/SMS pass-through | B11: =Customers!B6*Assumptions!$B$35 | C11: =Customers!C6*Assumptions!$B$35 | D11: =Customers!D6*Assumptions!$B$35 | E11: =Customers!E6*Assumptions!$B$35 | F11: =Customers!F6*Assumptions!$B$35 | G11: =Customers!G6*Assumptions!$B$35 | H11: =Customers!H6*Assumptions!$B$35 | I11: =Customers!I6*Assumptions!$B$35 | ... AK11: =Customers!AK6*Assumptions!$B$35 | AL11: =SUM(B11:M11) | AM11: =SUM(N11:Y11) | AN11: =SUM(Z11:AK11)
A12: Payment fees | B12: =B7*Assumptions!$B$36 | C12: =C7*Assumptions!$B$36 | D12: =D7*Assumptions!$B$36 | E12: =E7*Assumptions!$B$36 | F12: =F7*Assumptions!$B$36 | G12: =G7*Assumptions!$B$36 | H12: =H7*Assumptions!$B$36 | I12: =I7*Assumptions!$B$36 | ... AK12: =AK7*Assumptions!$B$36 | AL12: =SUM(B12:M12) | AM12: =SUM(N12:Y12) | AN12: =SUM(Z12:AK12)
A13: Support & Arabic QA | B13: =Customers!B6*Assumptions!$B$37 | C13: =Customers!C6*Assumptions!$B$37 | D13: =Customers!D6*Assumptions!$B$37 | E13: =Customers!E6*Assumptions!$B$37 | F13: =Customers!F6*Assumptions!$B$37 | G13: =Customers!G6*Assumptions!$B$37 | H13: =Customers!H6*Assumptions!$B$37 | I13: =Customers!I6*Assumptions!$B$37 | ... AK13: =Customers!AK6*Assumptions!$B$37 | AL13: =SUM(B13:M13) | AM13: =SUM(N13:Y13) | AN13: =SUM(Z13:AK13)
A14: TOTAL COGS | B14: =SUM(B9:B13) | C14: =SUM(C9:C13) | D14: =SUM(D9:D13) | E14: =SUM(E9:E13) | F14: =SUM(F9:F13) | G14: =SUM(G9:G13) | H14: =SUM(H9:H13) | I14: =SUM(I9:I13) | ... AK14: =SUM(AK9:AK13) | AL14: =SUM(B14:M14) | AM14: =SUM(N14:Y14) | AN14: =SUM(Z14:AK14)
A15: GROSS PROFIT | B15: =B7-B14 | C15: =C7-C14 | D15: =D7-D14 | E15: =E7-E14 | F15: =F7-F14 | G15: =G7-G14 | H15: =H7-H14 | I15: =I7-I14 | ... AK15: =AK7-AK14 | AL15: =SUM(B15:M15) | AM15: =SUM(N15:Y15) | AN15: =SUM(Z15:AK15)
A16: Gross margin % | B16: =IF(B7=0,0,B15/B7) | C16: =IF(C7=0,0,C15/C7) | D16: =IF(D7=0,0,D15/D7) | E16: =IF(E7=0,0,E15/E7) | F16: =IF(F7=0,0,F15/F7) | G16: =IF(G7=0,0,G15/G7) | H16: =IF(H7=0,0,H15/H7) | I16: =IF(I7=0,0,I15/I7) | ... AK16: =IF(AK7=0,0,AK15/AK7) | AL16: =IF(SUM(B7:M7)=0,0,SUM(B15:M15)/SUM(B7:M7)) | AM16: =IF(SUM(N7:Y7)=0,0,SUM(N15:Y15)/SUM(N7:Y7)) | AN16: =IF(SUM(Z7:AK7)=0,0,SUM(Z15:AK15)/SUM(Z7:AK7))
A18: Payroll | B18: =Headcount!C10 | C18: =Headcount!D10 | D18: =Headcount!E10 | E18: =Headcount!F10 | F18: =Headcount!G10 | G18: =Headcount!H10 | H18: =Headcount!I10 | I18: =Headcount!J10 | ... AK18: =Headcount!AL10 | AL18: =SUM(B18:M18) | AM18: =SUM(N18:Y18) | AN18: =SUM(Z18:AK18)
A19: Acquisition spend (new paying × CAC) | B19: =Customers!B4*Assumptions!$B$27 | C19: =Customers!C4*Assumptions!$B$27 | D19: =Customers!D4*Assumptions!$B$27 | E19: =Customers!E4*Assumptions!$B$27 | F19: =Customers!F4*Assumptions!$B$27 | G19: =Customers!G4*Assumptions!$B$27 | H19: =Customers!H4*Assumptions!$B$27 | I19: =Customers!I4*Assumptions!$B$27 | ... AK19: =Customers!AK4*Assumptions!$B$27 | AL19: =SUM(B19:M19) | AM19: =SUM(N19:Y19) | AN19: =SUM(Z19:AK19)
A20: Marketing base | B20: =Assumptions!$B$43 | C20: =Assumptions!$B$43 | D20: =Assumptions!$B$43 | E20: =Assumptions!$B$43 | F20: =Assumptions!$B$43 | G20: =Assumptions!$B$43 | H20: =Assumptions!$B$43 | I20: =Assumptions!$B$43 | ... AK20: =Assumptions!$B$43 | AL20: =SUM(B20:M20) | AM20: =SUM(N20:Y20) | AN20: =SUM(Z20:AK20)
A21: Software & tools | B21: =Assumptions!$B$40 | C21: =Assumptions!$B$40 | D21: =Assumptions!$B$40 | E21: =Assumptions!$B$40 | F21: =Assumptions!$B$40 | G21: =Assumptions!$B$40 | H21: =Assumptions!$B$40 | I21: =Assumptions!$B$40 | ... AK21: =Assumptions!$B$40 | AL21: =SUM(B21:M21) | AM21: =SUM(N21:Y21) | AN21: =SUM(Z21:AK21)
A22: Office & admin | B22: =Assumptions!$B$41 | C22: =Assumptions!$B$41 | D22: =Assumptions!$B$41 | E22: =Assumptions!$B$41 | F22: =Assumptions!$B$41 | G22: =Assumptions!$B$41 | H22: =Assumptions!$B$41 | I22: =Assumptions!$B$41 | ... AK22: =Assumptions!$B$41 | AL22: =SUM(B22:M22) | AM22: =SUM(N22:Y22) | AN22: =SUM(Z22:AK22)
A23: Legal & compliance | B23: =Assumptions!$B$42 | C23: =Assumptions!$B$42 | D23: =Assumptions!$B$42 | E23: =Assumptions!$B$42 | F23: =Assumptions!$B$42 | G23: =Assumptions!$B$42 | H23: =Assumptions!$B$42 | I23: =Assumptions!$B$42 | ... AK23: =Assumptions!$B$42 | AL23: =SUM(B23:M23) | AM23: =SUM(N23:Y23) | AN23: =SUM(Z23:AK23)
A24: TOTAL OPEX | B24: =SUM(B18:B23) | C24: =SUM(C18:C23) | D24: =SUM(D18:D23) | E24: =SUM(E18:E23) | F24: =SUM(F18:F23) | G24: =SUM(G18:G23) | H24: =SUM(H18:H23) | I24: =SUM(I18:I23) | ... AK24: =SUM(AK18:AK23) | AL24: =SUM(B24:M24) | AM24: =SUM(N24:Y24) | AN24: =SUM(Z24:AK24)
A25: EBITDA | B25: =B15-B24 | C25: =C15-C24 | D25: =D15-D24 | E25: =E15-E24 | F25: =F15-F24 | G25: =G15-G24 | H25: =H15-H24 | I25: =I15-I24 | ... AK25: =AK15-AK24 | AL25: =SUM(B25:M25) | AM25: =SUM(N25:Y25) | AN25: =SUM(Z25:AK25)
A26: EBITDA margin % | B26: =IF(B7=0,0,B25/B7) | C26: =IF(C7=0,0,C25/C7) | D26: =IF(D7=0,0,D25/D7) | E26: =IF(E7=0,0,E25/E7) | F26: =IF(F7=0,0,F25/F7) | G26: =IF(G7=0,0,G25/G7) | H26: =IF(H7=0,0,H25/H7) | I26: =IF(I7=0,0,I25/I7) | ... AK26: =IF(AK7=0,0,AK25/AK7) | AL26: =IF(SUM(B7:M7)=0,0,SUM(B25:M25)/SUM(B7:M7)) | AM26: =IF(SUM(N7:Y7)=0,0,SUM(N25:Y25)/SUM(N7:Y7)) | AN26: =IF(SUM(Z7:AK7)=0,0,SUM(Z25:AK25)/SUM(Z7:AK7))
A28: MRR (end of month) | B28: =B7 | C28: =C7 | D28: =D7 | E28: =E7 | F28: =F7 | G28: =G7 | H28: =H7 | I28: =I7 | ... AK28: =AK7 | AL28: =M28 | AM28: =Y28 | AN28: =AK28
A29: ARR run-rate | B29: =B28*12 | C29: =C28*12 | D29: =D28*12 | E29: =E28*12 | F29: =F28*12 | G29: =G28*12 | H29: =H28*12 | I29: =I28*12 | ... AK29: =AK28*12 | AL29: =M29 | AM29: =Y29 | AN29: =AK29
A30: Cumulative EBITDA | B30: =B25 | C30: =B30+C25 | D30: =C30+D25 | E30: =D30+E25 | F30: =E30+F25 | G30: =F30+G25 | H30: =G30+H25 | I30: =H30+I25 | J30: =I30+J25 | ... AK30: =AJ30+AK25 | AL30: =M30 | AM30: =Y30 | AN30: =AK30

Sheet Cash
A1: SAR | B1: Oct-26 | C1: Nov-26 | D1: Dec-26 | E1: Jan-27 | F1: Feb-27 | G1: Mar-27 | H1: Apr-27 | I1: May-27 | J1: Jun-27 | K1: Jul-27 | L1: Aug-27 | M1: Sep-27 | N1: Oct-27 | O1: Nov-27 | P1: Dec-27 | Q1: Jan-28 | R1: Feb-28 | S1: Mar-28 | T1: Apr-28 | U1: May-28 | V1: Jun-28 | W1: Jul-28 | X1: Aug-28 | Y1: Sep-28 | Z1: Oct-28 | AA1: Nov-28 | AB1: Dec-28 | AC1: Jan-29 | AD1: Feb-29 | AE1: Mar-29 | AF1: Apr-29 | AG1: May-29 | AH1: Jun-29 | AI1: Jul-29 | AJ1: Aug-29 | AK1: Sep-29
A2: Opening cash | B2: =Assumptions!$B$56 | C2: =B5 | D2: =C5 | E2: =D5 | F2: =E5 | G2: =F5 | H2: =G5 | I2: =H5 | J2: =I5 | ... AK2: =AJ5
A3: EBITDA | B3: ='P&L'!B25 | C3: ='P&L'!C25 | D3: ='P&L'!D25 | E3: ='P&L'!E25 | F3: ='P&L'!F25 | G3: ='P&L'!G25 | H3: ='P&L'!H25 | I3: ='P&L'!I25 | ... AK3: ='P&L'!AK25
A4: Equity raised | B4: =IF(1=Assumptions!$B$58,Assumptions!$B$57,0) | C4: =IF(2=Assumptions!$B$58,Assumptions!$B$57,0) | D4: =IF(3=Assumptions!$B$58,Assumptions!$B$57,0) | E4: =IF(4=Assumptions!$B$58,Assumptions!$B$57,0) | F4: =IF(5=Assumptions!$B$58,Assumptions!$B$57,0) | G4: =IF(6=Assumptions!$B$58,Assumptions!$B$57,0) | H4: =IF(7=Assumptions!$B$58,Assumptions!$B$57,0) | I4: =IF(8=Assumptions!$B$58,Assumptions!$B$57,0) | J4: =IF(9=Assumptions!$B$58,Assumptions!$B$57,0) | K4: =IF(10=Assumptions!$B$58,Assumptions!$B$57,0) | L4: =IF(11=Assumptions!$B$58,Assumptions!$B$57,0) | M4: =IF(12=Assumptions!$B$58,Assumptions!$B$57,0) | N4: =IF(13=Assumptions!$B$58,Assumptions!$B$57,0) | O4: =IF(14=Assumptions!$B$58,Assumptions!$B$57,0) | P4: =IF(15=Assumptions!$B$58,Assumptions!$B$57,0) | Q4: =IF(16=Assumptions!$B$58,Assumptions!$B$57,0) | R4: =IF(17=Assumptions!$B$58,Assumptions!$B$57,0) | S4: =IF(18=Assumptions!$B$58,Assumptions!$B$57,0) | T4: =IF(19=Assumptions!$B$58,Assumptions!$B$57,0) | U4: =IF(20=Assumptions!$B$58,Assumptions!$B$57,0) | V4: =IF(21=Assumptions!$B$58,Assumptions!$B$57,0) | W4: =IF(22=Assumptions!$B$58,Assumptions!$B$57,0) | X4: =IF(23=Assumptions!$B$58,Assumptions!$B$57,0) | Y4: =IF(24=Assumptions!$B$58,Assumptions!$B$57,0) | Z4: =IF(25=Assumptions!$B$58,Assumptions!$B$57,0) | AA4: =IF(26=Assumptions!$B$58,Assumptions!$B$57,0) | AB4: =IF(27=Assumptions!$B$58,Assumptions!$B$57,0) | AC4: =IF(28=Assumptions!$B$58,Assumptions!$B$57,0) | AD4: =IF(29=Assumptions!$B$58,Assumptions!$B$57,0) | AE4: =IF(30=Assumptions!$B$58,Assumptions!$B$57,0) | AF4: =IF(31=Assumptions!$B$58,Assumptions!$B$57,0) | AG4: =IF(32=Assumptions!$B$58,Assumptions!$B$57,0) | AH4: =IF(33=Assumptions!$B$58,Assumptions!$B$57,0) | AI4: =IF(34=Assumptions!$B$58,Assumptions!$B$57,0) | AJ4: =IF(35=Assumptions!$B$58,Assumptions!$B$57,0) | AK4: =IF(36=Assumptions!$B$58,Assumptions!$B$57,0)
A5: Closing cash | B5: =B2+B3+B4 | C5: =C2+C3+C4 | D5: =D2+D3+D4 | E5: =E2+E3+E4 | F5: =F2+F3+F4 | G5: =G2+G3+G4 | H5: =H2+H3+H4 | I5: =I2+I3+I4 | ... AK5: =AK2+AK3+AK4
A6: Runway (months at current burn) | B6: =IF(B3>=0,"∞",ROUND(B5/-B3,1)) | C6: =IF(C3>=0,"∞",ROUND(C5/-C3,1)) | D6: =IF(D3>=0,"∞",ROUND(D5/-D3,1)) | E6: =IF(E3>=0,"∞",ROUND(E5/-E3,1)) | F6: =IF(F3>=0,"∞",ROUND(F5/-F3,1)) | G6: =IF(G3>=0,"∞",ROUND(G5/-G3,1)) | H6: =IF(H3>=0,"∞",ROUND(H5/-H3,1)) | I6: =IF(I3>=0,"∞",ROUND(I5/-I3,1)) | ... AK6: =IF(AK3>=0,"∞",ROUND(AK5/-AK3,1))
A8: Minimum cash balance (36m) | B8: =MIN(B5:AK5)

Sheet Unit Economics
A1: Per-plan unit economics (monthly, SAR)
B3: Starter | C3: Pro | D3: Agency | E3: Enterprise
A4: Price (ex-VAT, blended for annual mix) | B4: =Assumptions!$B$6*(1-Assumptions!$B$11*Assumptions!$B$10) | C4: =Assumptions!$B$7*(1-Assumptions!$B$11*Assumptions!$B$10) | D4: =Assumptions!$B$8*(1-Assumptions!$B$11*Assumptions!$B$10) | E4: =Assumptions!$B$9
A5: + Top-ups / seats | B5: =B4*Assumptions!$B$12 | C5: =C4*Assumptions!$B$12 | D5: =D4*Assumptions!$B$12 | E5: =E4*Assumptions!$B$12
A6: Revenue per brand | B6: =B4+B5 | C6: =C4+C5 | D6: =D4+D5 | E6: =E4+E5
A7: AI model + media | B7: =Assumptions!$B$30 | C7: =Assumptions!$B$31 | D7: =Assumptions!$B$32 | E7: =Assumptions!$B$33
A8: Infra + messaging + support | B8: =Assumptions!$B$34+Assumptions!$B$35+Assumptions!$B$37 | C8: =Assumptions!$B$34+Assumptions!$B$35+Assumptions!$B$37 | D8: =Assumptions!$B$34+Assumptions!$B$35+Assumptions!$B$37 | E8: =Assumptions!$B$34+Assumptions!$B$35+Assumptions!$B$37
A9: Payment fees | B9: =B6*Assumptions!$B$36 | C9: =C6*Assumptions!$B$36 | D9: =D6*Assumptions!$B$36 | E9: =E6*Assumptions!$B$36
A10: Gross profit per brand | B10: =B6-B7-B8-B9 | C10: =C6-C7-C8-C9 | D10: =D6-D7-D8-D9 | E10: =E6-E7-E8-E9
A11: Gross margin % | B11: =B10/B6 | C11: =C10/C6 | D11: =D10/D6 | E11: =E10/E6
A12: Expected lifetime (months) = 1/churn | B12: =1/Assumptions!$B$26 | C12: =1/Assumptions!$B$26 | D12: =1/Assumptions!$B$26 | E12: =1/Assumptions!$B$26
A13: LTV (gross profit × lifetime) | B13: =B10*B12 | C13: =C10*C12 | D13: =D10*D12 | E13: =E10*E12
A14: CAC | B14: =Assumptions!$B$27 | C14: =Assumptions!$B$27 | D14: =Assumptions!$B$27 | E14: =Assumptions!$B$27
A15: LTV : CAC | B15: =B13/B14 | C15: =C13/C14 | D15: =D13/D14 | E15: =E13/E14
A16: CAC payback (months) | B16: =B14/B10 | C16: =C14/C10 | D16: =D14/D10 | E16: =E14/E10
A20: Blended (weighted by plan mix)
A21: Blended revenue per brand | B21: =B6*Assumptions!$B$15+C6*Assumptions!$B$16+D6*Assumptions!$B$17+E6*Assumptions!$B$18
A22: Blended gross profit per brand | B22: =B10*Assumptions!$B$15+C10*Assumptions!$B$16+D10*Assumptions!$B$17+E10*Assumptions!$B$18
A23: Blended gross margin | B23: =B22/B21
A24: Blended LTV | B24: =B13*Assumptions!$B$15+C13*Assumptions!$B$16+D13*Assumptions!$B$17+E13*Assumptions!$B$18
A25: Blended LTV:CAC | B25: =B24/Assumptions!$B$27
A26: Blended CAC payback (months) | B26: =Assumptions!$B$27/B22
